Workbook

Sheet INFO
B2: Ticker | E2: AAPL | I2: Description
B3: Name | E3: {=_xldudf_WISEPRICE($E$2,B3)} -> Apple Inc. | I3: {=_xldudf_WISEPRICE(E2,I2)} -> Apple Inc. is a global technology corporation that specializes in the conceptualization, production, and sale of a diverse suite of electronic devices. Its comprehensive hardware lineup features the well-known iPhone smartphones, Mac personal computers, and versatile iPad tablets. The company also supplies a range of wearables, smart home products, and accessories, including AirPods, Apple TV, Apple Watch, items from the Beats brand, and HomePod speakers. Beyond its device offerings, Apple delivers essential support services like AppleCare and robust cloud solutions. It oversees key digital platforms, prominently the App Store, which acts as a central hub for customers to discover and download countless applications and digital content, from e-books and music to videos, games, and podcasts. The company also generates revenue via advertising, leveraging both its proprietary ad platforms and third-party licensing deals. Apple's ecosystem is further bolstered by a wide array of subscription-based services: Apple Arcade for gaming, Apple Fitness+ for personalized wellness, Apple Music for curated audio experiences and on-demand radio, Apple News+ for access to news and magazines, and Apple TV+ for exclusive original video programming. Its financial services portfolio includes the co-branded Apple Card and the mobile payment system, Apple Pay. Additionally, Apple strategically licenses its intellectual property. The company serves a broad clientele that spans individual consumers, small and medium-sized enterprises, as well as institutional clients in the education, corporate, and governmental sectors. Products are distributed through a multi-channel strategy, utilizing Apple's own physical retail locations and online storefronts, a dedicated direct sales team, and collaborations with external partners such as mobile network providers, wholesalers, general retailers, and authorized resellers. The App Store additionally functions as the primary conduit for third-party applications designed for its devices. Founded in 1976, Apple Inc. is headquartered in Cupertino, California.
B4: Market cap | E4: {=_xldudf_WISE(E2,B4,Y13)/1000000} -> 4810109.1 | F4: 2577253
B5: Sector | E5: {=_xldudf_WISEPRICE($E$2,B5:B10)} -> Technology
B6: Industry | E6: Consumer Electronics
B7: Exchange Short Name | E7: NASDAQ
B8: IPODate | E8: 1980-12-12
B9: Full Time Employees | E9: 166000
B10: Website | E10: https://www.apple.com
B11: Analysis Year | E11: 2023
B13: Year | G13: =H13-1 -> 2006 | H13: =I13-1 -> 2007 | I13: =J13-1 -> 2008 | J13: =K13-1 -> 2009 | K13: =L13-1 -> 2010 | L13: =M13-1 -> 2011 | M13: =N13-1 -> 2012 | N13: =O13-1 -> 2013 | ... W13: =X13-1 -> 2022 | X13: =E11 -> 2023 | Y13: TTM | AA13: Z-score (Default Risk)
B14: Revenue | G14: {=_xldudf_WISE($E$2,$B14:$B15,G$13:Y$13)/1000000} -> 19315 | H14: 24006 | I14: 32479 | J14: 42603 | K14: 65225 | L14: 108249 | M14: 156508 | N14: 170910 | O14: 182795 | P14: 233715 | Q14: 215639 | R14: 229234 | S14: 265595 | T14: 260174 | U14: 274515 | V14: 365817 | W14: 394328 | X14: 383285 | Y14: 451442 | AD14: =E11 -> 2023 | AE14: TTM
B15: Gross Profit | G15: 5598 | H15: 8154 | I15: 11145 | J15: 16852 | K15: 25684 | L15: 43818 | M15: 68662 | N15: 64304 | O15: 70537 | P15: 93626 | Q15: 84263 | R15: 88186 | S15: 101839 | T15: 98392 | U15: 104956 | V15: 152836 | W15: 170782 | X15: 169148 | Y15: 216071 | AA15: Current Assets | AD15: {=_xldudf_WISE($E$2,"Total current assets",AD$14:AE$14)/1000000} -> 143566 | AE15: 144114
B16: Gross Margin | G16: =IFERROR((G15/G14),"") -> 0.28982656 | H16: =IFERROR((H15/H14),"") -> 0.33966508 | I16: =IFERROR((I15/I14),"") -> 0.3431448 | J16: =IFERROR((J15/J14),"") -> 0.395559 | K16: =IFERROR((K15/K14),"") -> 0.39377539 | L16: =IFERROR((L15/L14),"") -> 0.40478896 | M16: =IFERROR((M15/M14),"") -> 0.4387124 | N16: =IFERROR((N15/N14),"") -> 0.37624481 | ... Y16: =IFERROR((Y15/Y14),"") -> 0.47862405 | AA16: Current Liabilities | AD16: {=_xldudf_WISE($E$2,"Total current liabilities",AD$14:AE$14)/1000000} -> 145308 | AE16: 134641
B17: EBITDA | G17: {=_xldudf_WISE($E$2,$B17:$B18,G$13:Y$13)/1000000} -> 2678 | H17: 4724 | I17: 7304 | J17: 12029 | K17: 19412 | L17: 36019 | M17: 59040 | N17: 57048 | O17: 61813 | P17: 84505 | Q17: 73333 | R17: 76569 | S17: 87046 | T17: 81860 | U17: 81020 | V17: 123136 | W17: 133138 | X17: 129188 | Y17: 160332 | AA17: Net Working Capital | AD17: {=_xldudf_WISE($E$2,"Working capital",AD$14:AE$14)/1000000} -> -1742 | AE17: 9473
B18: Net Income | G18: 1989 | H18: 3495 | I18: 4834 | J18: 8235 | K18: 14013 | L18: 25922 | M18: 41733 | N18: 37037 | O18: 39510 | P18: 53394 | Q18: 45687 | R18: 48351 | S18: 59531 | T18: 55256 | U18: 57411 | V18: 94680 | W18: 99803 | X18: 96995 | Y18: 122575 | AA18: Total Assets | AD18: {=_xldudf_WISE($E$2,$AA18:$AA20,AD$14:AE$14)/1000000} -> 352583 | AE18: 371082
B19: Net Margin | G19: =IFERROR((G18/G14),"") -> 0.10297696 | H19: =IFERROR((H18/H14),"") -> 0.1455886 | I19: =IFERROR((I18/I14),"") -> 0.14883463 | J19: =IFERROR((J18/J14),"") -> 0.19329625 | K19: =IFERROR((K18/K14),"") -> 0.21484094 | L19: =IFERROR((L18/L14),"") -> 0.23946642 | M19: =IFERROR((M18/M14),"") -> 0.26665091 | N19: =IFERROR((N18/N14),"") -> 0.2167047 | ... Y19: =IFERROR((Y18/Y14),"") -> 0.27151882 | AA19: Retained Earnings | AD19: -214 | AE19: 12359
B20: EPS | G20: {=_xldudf_WISE(E2,B20,G13:Y13)} -> 0.08 | H20: 0.14 | I20: 0.2 | J20: 0.33 | K20: 0.55 | L20: 1 | M20: 1.59 | N20: 1.43 | O20: 1.62 | P20: 2.32 | Q20: 2.09 | R20: 2.32 | S20: 3 | T20: 2.99 | U20: 3.31 | V20: 5.67 | W20: 6.15 | X20: 6.16 | Y20: 8.29 | AA20: Operating Income | AD20: 114301 | AE20: 147366
B21: Free Cash Flow | G21: {=_xldudf_WISE($E$2,$B21,G$13:Y$13)/1000000} -> 1563 | H21: 4484 | I21: 8397 | J21: 8946 | K21: 16474 | L21: 30077 | M21: 41454 | N21: 44590 | O21: 49900 | P21: 69778 | Q21: 52683 | R21: 51430 | S21: 64121 | T21: 58896 | U21: 73365 | V21: 92953 | W21: 111443 | X21: 99584 | Y21: 129174 | AA21: Basic Shares Outstanding | AD21: {=_xldudf_WISE($E$2,"Weighted Average Shs Out",AD$14:AE$14)/1000000} -> 15744.231 | AE21: 14710.718
B22: Rev % | H22: =IFERROR((H14-G14)/G14,"") -> 0.24286824 | I22: =IFERROR((I14-H14)/H14,"") -> 0.35295343 | J22: =IFERROR((J14-I14)/I14,"") -> 0.3117091 | K22: =IFERROR((K14-J14)/J14,"") -> 0.53099547 | L22: =IFERROR((L14-K14)/K14,"") -> 0.65962438 | M22: =IFERROR((M14-L14)/L14,"") -> 0.44581474 | N22: =IFERROR((N14-M14)/M14,"") -> 0.092020855 | O22: =IFERROR((O14-N14)/N14,"") -> 0.069539524 | ... X22: =IFERROR((X14-W14)/W14,"") -> -0.028004605 | AA22: Stock Price | AD22: {=_xldudf_WISEPRICE($E$2,"price")} -> 327.5 | AE22: {=_xldudf_WISEPRICE($E$2,"price")} -> 327.5
B23: Gross Profit % | H23: =IFERROR((H15-G15)/G15,"") -> 0.45659164 | I23: =IFERROR((I15-H15)/H15,"") -> 0.36681383 | J23: =IFERROR((J15-I15)/I15,"") -> 0.51206819 | K23: =IFERROR((K15-J15)/J15,"") -> 0.5240921 | L23: =IFERROR((L15-K15)/K15,"") -> 0.70604267 | M23: =IFERROR((M15-L15)/L15,"") -> 0.56698161 | N23: =IFERROR((N15-M15)/M15,"") -> -0.063470333 | O23: =IFERROR((O15-N15)/N15,"") -> 0.096930207 | ... X23: =IFERROR((X15-W15)/W15,"") -> -0.009567753 | AA23: Market Cap | AD23: {=_xldudf_WISE($E$2,$AA23:$AA25,AD$14:AE$14)/1000000} -> 2695569.8 | AE23: 4810109.1
B24: Net Income % | H24: =IFERROR((H18-G18)/G18,"") -> 0.7571644 | I24: =IFERROR((I18-H18)/H18,"") -> 0.38311874 | J24: =IFERROR((J18-I18)/I18,"") -> 0.70355813 | K24: =IFERROR((K18-J18)/J18,"") -> 0.70163934 | L24: =IFERROR((L18-K18)/K18,"") -> 0.84985371 | M24: =IFERROR((M18-L18)/L18,"") -> 0.60994522 | N24: =IFERROR((N18-M18)/M18,"") -> -0.11252486 | O24: =IFERROR((O18-N18)/N18,"") -> 0.066771067 | ... X24: =IFERROR((X18-W18)/W18,"") -> -0.028135427 | AA24: Total Liabilities | AD24: 290437 | AE24: 264591
B25: EPS % | H25: =IFERROR((H20-G20)/G20,"") -> 0.75 | I25: =IFERROR((I20-H20)/H20,"") -> 0.42857143 | J25: =IFERROR((J20-I20)/I20,"") -> 0.65 | K25: =IFERROR((K20-J20)/J20,"") -> 0.66666667 | L25: =IFERROR((L20-K20)/K20,"") -> 0.81818182 | M25: =IFERROR((M20-L20)/L20,"") -> 0.59 | N25: =IFERROR((N20-M20)/M20,"") -> -0.10062893 | O25: =IFERROR((O20-N20)/N20,"") -> 0.13286713 | ... X25: =IFERROR((X20-W20)/W20,"") -> 0.0016260163 | AA25: Revenue | AD25: 383285 | AE25: 451442
B26: Free Cash Flow % | H26: =IFERROR((H21-G21)/G21,"") -> 1.868842 | I26: =IFERROR((I21-H21)/H21,"") -> 0.87265834 | J26: =IFERROR((J21-I21)/I21,"") -> 0.065380493 | K26: =IFERROR((K21-J21)/J21,"") -> 0.8414934 | L26: =IFERROR((L21-K21)/K21,"") -> 0.82572539 | M26: =IFERROR((M21-L21)/L21,"") -> 0.37826246 | N26: =IFERROR((N21-M21)/M21,"") -> 0.075650118 | O26: =IFERROR((O21-N21)/N21,"") -> 0.119085 | ... X26: =IFERROR((X21-W21)/W21,"") -> -0.10641314
B27: Cash And Cash Equivalents | G27: {=_xldudf_WISE($E$2,$B27:$B30,G$13:Y$13)/1000000} -> 6392 | H27: 9352 | I27: 11875 | J27: 5263 | K27: 11261 | L27: 9815 | M27: 10746 | N27: 14259 | O27: 13844 | P27: 21120 | Q27: 20484 | R27: 20289 | S27: 25913 | T27: 48844 | U27: 38016 | V27: 34940 | W27: 23646 | X27: 29965 | Y27: 36328 | AA27: Coefficient | AD27: Variables
B28: Selling General And Administrative Expenses | G28: 2433 | H28: 2963 | I28: 3761 | J28: 4149 | K28: 5517 | L28: 7599 | M28: 10040 | N28: 10830 | O28: 11993 | P28: 14329 | Q28: 14194 | R28: 15261 | S28: 16705 | T28: 18245 | U28: 19916 | V28: 21973 | W28: 25094 | X28: 24932 | Y28: 28667 | AA28: 1.2 | AD28: =(AD15-AD16)/AD18 -> -0.0049406806 | AE28: =(AE15-AE16)/AE18 -> 0.02552805
B29: Short Term Debt | G29: 0 | H29: 0 | I29: 0 | J29: 0 | K29: 0 | L29: 0 | M29: 0 | N29: 0 | O29: 6308 | P29: 10999 | Q29: 11605 | R29: 18473 | S29: 20748 | T29: 16240 | U29: 15229 | V29: 17141 | W29: 22773 | X29: 17382 | Y29: 10307 | AA29: 1.4 | AD29: =AD19/AD18 -> -0.00060694929 | AE29: =AE19/AE18 -> 0.033305307
B30: Research And Development Expenses | G30: 712 | H30: 782 | I30: 1109 | J30: 1333 | K30: 1782 | L30: 2429 | M30: 3381 | N30: 4475 | O30: 6041 | P30: 8067 | Q30: 10045 | R30: 11581 | S30: 14236 | T30: 16217 | U30: 18752 | V30: 21914 | W30: 26251 | X30: 29915 | Y30: 40038 | AA30: 3.3 | AD30: =AD20/AD18 -> 0.32418182 | AE30: =AE20/AE18 -> 0.39712516
B31: Revenue Per Share | G31: =IFERROR(G14/G45,"") -> 0.78609799 | H31: =IFERROR(H14/H45,"") -> 0.96408957 | I31: =IFERROR(I14/I45,"") -> 1.2857933 | J31: =IFERROR(J14/J45,"") -> 1.6775367 | K31: =IFERROR(K14/K45,"") -> 2.5191216 | L31: =IFERROR(L14/L45,"") -> 4.1275357 | M31: =IFERROR(M14/M45,"") -> 5.912671 | N31: =IFERROR(N14/N45,"") -> 6.5516556 | ... Y31: =IFERROR(Y14/Y45,"") -> 30.568695 | AA31: 0.6 | AD31: =AD23/AD24 -> 9.2810826 | AE31: =AE23/AE24 -> 18.179413
B32: Net Income Per Share | G32: =IFERROR(G18/G45,"") -> 0.080949982 | H32: =IFERROR(H18/H45,"") -> 0.14036045 | I32: =IFERROR(I18/I45,"") -> 0.19137057 | J32: =IFERROR(J18/J45,"") -> 0.32426155 | K32: =IFERROR(K18/K45,"") -> 0.54121044 | L32: =IFERROR(L18/L45,"") -> 0.98840619 | M32: =IFERROR(M18/M45,"") -> 1.5766191 | N32: =IFERROR(N18/N45,"") -> 1.4197746 | ... Y32: =IFERROR(Y18/Y45,"") -> 8.299976 | AA32: 1 | AD32: =AD25/AD18 -> 1.0870774 | AE32: =AE25/AE18 -> 1.2165559
B33: Free Cash Flow Per Share | G33: =IFERROR(G21/G45,"") -> 0.063612279 | H33: =IFERROR(H21/H45,"") -> 0.18007905 | I33: =IFERROR(I21/I45,"") -> 0.33242422 | J33: =IFERROR(J21/J45,"") -> 0.3522579 | K33: =IFERROR(K21/K45,"") -> 0.63625924 | L33: =IFERROR(L21/L45,"") -> 1.1468364 | M33: =IFERROR(M21/M45,"") -> 1.5660788 | N33: =IFERROR(N21/N45,"") -> 1.7093109 | ... Y33: =IFERROR(Y21/Y45,"") -> 8.746817 | AD33: =SUMPRODUCT(AA28:AA32,AD28:AD32) -> 7.7187484 | AE33: =SUMPRODUCT(AA28:AA32,AE28:AE32) -> 13.511978
B34: Cash Per Share | G34: =IFERROR(G27/G45,"") -> 0.26014695 | H34: =IFERROR(H27/H45,"") -> 0.37557967 | I34: =IFERROR(I27/I45,"") -> 0.47011286 | J34: =IFERROR(J27/J45,"") -> 0.20723601 | K34: =IFERROR(K27/K45,"") -> 0.43492262 | L34: =IFERROR(L27/L45,"") -> 0.37424607 | M34: =IFERROR(M27/M45,"") -> 0.40597006 | N34: =IFERROR(N27/N45,"") -> 0.54660381 | ... Y34: =IFERROR(Y27/Y45,"") -> 2.4598942
B35: Tangible Book Value Per Share | G35: {=IF(_xldudf_WISE($E$2,$B35,G$13)="unavailable","",_xldudf_WISE($E$2,$B35,G$13))} -> 0.41495964 | H35: {=IF(_xldudf_WISE($E$2,$B35,H$13)="unavailable","",_xldudf_WISE($E$2,$B35,H$13))} -> 0.58635983 | I35: {=IF(_xldudf_WISE($E$2,$B35,I$13)="unavailable","",_xldudf_WISE($E$2,$B35,I$13))} -> 0.88334513 | J35: {=IF(_xldudf_WISE($E$2,$B35,J$13)="unavailable","",_xldudf_WISE($E$2,$B35,J$13))} -> 1.2472568 | K35: {=IF(_xldudf_WISE($E$2,$B35,K$13)="unavailable","",_xldudf_WISE($E$2,$B35,K$13))} -> 1.8342086 | L35: {=IF(_xldudf_WISE($E$2,$B35,L$13)="unavailable","",_xldudf_WISE($E$2,$B35,L$13))} -> 2.789223 | M35: {=IF(_xldudf_WISE($E$2,$B35,M$13)="unavailable","",_xldudf_WISE($E$2,$B35,M$13))} -> 4.3114155 | N35: {=IF(_xldudf_WISE($E$2,$B35,N$13)="unavailable","",_xldudf_WISE($E$2,$B35,N$13))} -> 4.5463654 | ... Y35: {=IF(_xldudf_WISE($E$2,$B35,Y$13)="unavailable","",_xldudf_WISE($E$2,$B35,Y$13))} -> 5.7887725 | AA35: Financial Leverage
B36: Debt To Equity | G36: {=_xldudf_WISE(E2,B36:B43,G13:Y13)} -> 0 | H36: 0 | I36: 0 | J36: 0 | K36: 0 | L36: 0 | M36: 0 | N36: 0.13727347 | O36: 0.31641371 | P36: 0.5389636 | Q36: 0.67861738 | R36: 0.86298089 | S36: 1.0684667 | T36: 1.1940478 | U36: 1.8714397 | V36: 2.1639246 | W36: 2.6144616 | X36: 1.994175 | Y36: 0.79547567 | AD36: =E11 -> 2023 | AE36: TTM
B37: Net Debt To EBITDA | G37: -2.3868559 | H37: -1.9796782 | I37: -1.6258215 | J37: -0.43752598 | K37: -0.58010509 | L37: -0.27249507 | M37: -0.1820122 | N37: 0.047346094 | O37: 0.34703056 | P37: 0.51130702 | Q37: 0.90747685 | R37: 1.2458175 | S37: 1.017508 | T37: 0.72322258 | U37: 1.0400148 | V37: 0.82495777 | W37: 0.81745257 | X37: 0.72735084 | Y37: 0.30176758 | AA37: Total Liabilities | AD37: {=_xldudf_WISE($E$2,$AA37:$AA40,AD$36:AE$36)/1000000} -> 290437 | AE37: 264591
B38: PE Ratio | G38: 32.675951 | H38: 37.958109 | I38: 23.387538 | J38: 19.766742 | K38: 18.971948 | L38: 14.416186 | M38: 14.946172 | N38: 12.060258 | O38: 15.519672 | P38: 12.361547 | Q38: 13.497731 | R38: 16.630087 | S38: 18.792325 | T38: 18.288816 | U38: 33.935934 | V38: 25.916254 | W38: 24.441824 | X38: 27.790812 | Y38: 39.505428 | AA38: Total Assets | AD38: 352583 | AE38: 371082
B39: PB Ratio | G39: 6.5096621 | H39: 9.1290662 | I39: 5.0704291 | J39: 5.1447256 | K39: 5.5628446 | L39: 4.8775875 | M39: 5.2766144 | N39: 3.6153735 | O39: 5.4970751 | P39: 5.5299942 | Q39: 4.808387 | R39: 5.998503 | S39: 10.441038 | T39: 11.167965 | U39: 29.81827 | V39: 38.892865 | W39: 48.14034 | X39: 43.374791 | Y39: 45.241008 | AA39: Total Equity | AD39: 62146 | AE39: 106491
B40: Current Ratio | G40: 2.2519013 | H40: 2.3659483 | I40: 2.6411407 | J40: 2.7424822 | K40: 2.0112923 | L40: 1.6084376 | M40: 1.4958487 | N40: 1.6786385 | O40: 1.0801128 | P40: 1.1087706 | Q40: 1.3526694 | R40: 1.2760628 | S40: 1.1329262 | T40: 1.5401256 | U40: 1.3636044 | V40: 1.0745531 | W40: 0.87935603 | X40: 0.98801167 | Y40: 1.0703575 | AA40: EBITDA | AD40: 129188 | AE40: 160332
B41: ROE | G41: 0.19921875 | H41: 0.24050372 | I41: 0.21680047 | J41: 0.26027181 | K41: 0.2932142 | L41: 0.33834106 | M41: 0.3530412 | N41: 0.2997758 | O41: 0.35420047 | P41: 0.44735453 | Q41: 0.3562367 | R41: 0.36070184 | S41: 0.55560118 | T41: 0.61064451 | U41: 0.87866359 | V41: 1.5007133 | W41: 1.9695887 | X41: 1.5607601 | Y41: 1.4668924
B42: Dividend | G42: 0 | H42: 0 | I42: 0 | J42: 0 | K42: 0 | L42: 0 | M42: 5.3 | N42: 11.8 | O42: 7.28 | P42: 2.03 | Q42: 2.23 | R42: 2.46 | S42: 2.82 | T42: 3.04 | U42: 2.615 | V42: 0.865 | W42: 0.91 | X42: 0.95 | Y42: 1.05 | AA42: Debt-to-Equity | AD42: =AD37/AD39 -> 4.6734625 | AE42: =AE37/AE39 -> 2.4846325
...

Sheet CHARTS
B2: Charts

Sheet FS
B2: Ticker | C2: AAPL
B4: Income Statement | G4: =H4-1 -> 2016 | H4: =I4-1 -> 2017 | I4: =J4-1 -> 2018 | J4: =K4-1 -> 2019 | K4: =L4-1 -> 2020 | L4: =M4-1 -> 2021 | M4: =N4-1 -> 2022 | N4: 2023 | P4: Key Metrics | U4: =G4 -> 2016 | V4: =H4 -> 2017 | W4: =I4 -> 2018 | X4: =J4 -> 2019 | Y4: =K4 -> 2020 | Z4: =L4 -> 2021 | AA4: =M4 -> 2022 | AB4: =N4 -> 2023 | AD4: Financial Growth | AI4: =U4 -> 2016 | AJ4: =V4 -> 2017 | AK4: =W4 -> 2018 | AL4: =X4 -> 2019 | AM4: =Y4 -> 2020 | AN4: =Z4 -> 2021 | AO4: =AA4 -> 2022 | AP4: =AB4 -> 2023 | AR4: Analyst Estimates | AW4: =AX4-1 -> 2023 | AX4: 2024
B5: (in millions $) | P5: Revenue Per Share | U5: {=_xldudf_WISE(C2,P5:P60,U4:AB4)} -> 9.854053 | V5: 10.984444 | W5: 13.399334 | X5: 14.085283 | Y5: 15.820258 | Z5: 21.903541 | AA5: 24.317273 | AB5: 24.344473 | AD5: Revenue Growth | AI5: {=_xldudf_WISE(C2,AD5:AD38,AI4:AP4)} -> -0.0773 | AJ5: 0.063 | AK5: 0.1586 | AL5: -0.0204 | AM5: 0.0551 | AN5: 0.3326 | AO5: 0.0779 | AP5: -0.028 | AR5: Estimated Revenue Low | AW5: {=_xldudf_WISE($C$2,$AR5:$AR19,AW$4:AX$4)/1000000} -> 366438.57 | AX5: 389950.95
B6: Revenue | G6: {=_xldudf_WISE($C$2,$B6:$B8,G$4:N$4)/1000000} -> 215639 | H6: 229234 | I6: 265595 | J6: 260174 | K6: 274515 | L6: 365817 | M6: 394328 | N6: 383285 | P6: Net Income Per Share | U6: 2.0877583 | V6: 2.3168851 | W6: 3.0033537 | X6: 2.9914458 | Y6: 3.3085873 | Z6: 5.6690293 | AA6: 6.1546144 | AB6: 6.1606693 | AD6: Gross Profit Growth | AI6: -0.1 | AJ6: 0.0466 | AK6: 0.1548 | AL6: -0.0338 | AM6: 0.0667 | AN6: 0.4562 | AO6: 0.1174 | AP6: -0.0096 | AR6: Estimated Revenue High | AW6: 401241.69 | AX6: 392209.91
B7: Cost Of Revenue | G7: 131376 | H7: 141048 | I7: 163756 | J7: 161782 | K7: 169559 | L7: 212981 | M7: 223546 | N7: 214137 | P7: Operating Cash Flow Per Share | U7: 3.0265573 | V7: 3.077536 | W7: 3.9065645 | X7: 3.7566855 | Y7: 4.6492304 | Z7: 6.2293459 | AA7: 7.5327626 | AB7: 7.0211749 | AD7: Ebitgrowth | AI7: -0.1423 | AJ7: 0.057 | AK7: 0.1465 | AL7: -0.0897 | AM7: 0.0094 | AN7: 0.5987 | AO7: 0.091 | AP7: -0.0358 | AR7: Estimated Revenue AVG | AW7: 381623 | AX7: 390480.7
B8: Gross Profit | G8: 84263 | H8: 88186 | I8: 101839 | J8: 98392 | K8: 104956 | L8: 152836 | M8: 170782 | N8: 169148 | P8: Free Cash Flow Per Share | U8: 2.4074545 | V8: 2.4644247 | W8: 3.2349204 | X8: 3.1885079 | Y8: 4.2280139 | Z8: 5.565624 | AA8: 6.8724256 | AB8: 6.3251104 | AD8: Operating Income Growth | AI8: -0.1573 | AJ8: 0.022 | AK8: 0.1557 | AL8: -0.0983 | AM8: 0.0369 | AN8: 0.6436 | AO8: 0.0963 | AP8: -0.043 | AR8: Estimated EBITDA Low | AW8: 132260.49 | AX8: 140746.93
B9: Gross Profit Ratio | G9: {=_xldudf_WISE($C$2,$B9,G$4:N$4)} -> 0.39075956 | H9: 0.38469861 | I9: 0.38343719 | J9: 0.37817768 | K9: 0.38233248 | L9: 0.4177936 | M9: 0.43309631 | N9: 0.4413113 | P9: Cash Per Share | U9: 3.0687813 | V9: 3.554608 | W9: 3.3449019 | X9: 5.4439484 | Y9: 5.2410314 | Z9: 3.7505527 | AA9: 2.9787932 | AB9: 3.909686 | AD9: Net Income Growth | AI9: -0.1443 | AJ9: 0.0583 | AK9: 0.2312 | AL9: -0.0718 | AM9: 0.039 | AN9: 0.6492 | AO9: 0.0541 | AP9: -0.0281 | AR9: Estimated EBITDA High | AW9: 144822.15 | AX9: 141562.27
P10: Book Value Per Share | U10: 5.8605931 | V10: 6.4232692 | W10: 5.4055928 | X10: 4.8988335 | Y10: 3.7654767 | Z10: 3.7775566 | AA10: 3.1248221 | AB10: 3.9472236 | AD10: Epsgrowth | AI10: -0.0991 | AJ10: 0.11 | AK10: 0.2931 | AL10: -0.0033 | AM10: 0.107 | AN10: 0.713 | AO10: 0.0847 | AP10: 0.0016 | AR10: Estimated EBITDA AVG | AW10: 137741.08 | AX10: 140938.13
B11: Research And Development Expenses | G11: {=_xldudf_WISE($C$2,$B11:$B14,G$4:N$4)/1000000} -> 10045 | H11: 11581 | I11: 14236 | J11: 16217 | K11: 18752 | L11: 21914 | M11: 26251 | N11: 29915 | P11: Tangible Book Value Per Share | U11: 5.4666851 | V11: 6.0392062 | W11: 5.4055928 | X11: 4.8988335 | Y11: 3.7654767 | Z11: 3.7775566 | AA11: 3.1248221 | AB11: 3.9472236 | AD11: Epsdiluted Growth | AI11: -0.0957 | AJ11: 0.1058 | AK11: 0.2957 | AL11: -0.0034 | AM11: 0.1044 | AN11: 0.7104 | AO11: 0.0891 | AP11: 0.0033 | AR11: Estimated EBIT Low | AW11: 122730.09 | AX11: 130605.02
B12: Selling General And Administrative Expenses | G12: 14194 | H12: 15261 | I12: 16705 | J12: 18245 | K12: 19916 | L12: 21973 | M12: 25094 | N12: 24932 | P12: Shareholders Equity Per Share | U12: 5.8605931 | V12: 6.4232692 | W12: 5.4055928 | X12: 4.8988335 | Y12: 3.7654767 | Z12: 3.7775566 | AA12: 3.1248221 | AB12: 3.9472236 | AD12: Weighted Average Shares Growth | AI12: -0.0491 | AJ12: -0.0464 | AK12: -0.0502 | AL12: -0.0681 | AM12: -0.0606 | AN12: -0.0375 | AO12: -0.0291 | AP12: -0.0291 | AR12: Estimated EBIT High | AW12: 134386.59 | AX12: 131361.6
B13: Other Expenses | G13: 0 | H13: 0 | I13: 0 | J13: 0 | K13: 0 | L13: 0 | M13: 0 | N13: 0 | P13: Interest Debt Per Share | U13: 4.0436351 | V13: 5.6544722 | W13: 5.9391546 | X13: 6.0430388 | Y13: 7.2124332 | Z13: 8.3327186 | AA13: 8.3504754 | AB13: 8.1212604 | AD13: Weighted Average Shares Diluted Growth | AI13: -0.0505 | AJ13: -0.0452 | AK13: -0.0479 | AL13: -0.0702 | AM13: -0.0574 | AN13: -0.0378 | AO13: -0.032 | AP13: -0.0314 | AR13: Estimated EBIT AVG | AW13: 127815.77 | AX13: 130782.45
B14: Operating Expenses | G14: 24239 | H14: 26842 | I14: 30941 | J14: 34462 | K14: 38668 | L14: 43887 | M14: 51345 | N14: 54847 | P14: Market Cap | U14: 616670830400 | V14: 804081337040 | W14: 1118725911520 | X14: 1010566792560 | Y14: 1948295921320 | Z14: 2453750882240 | AA14: 2439367314090 | AB14: 2695569789510 | AD14: Dividendsper Share Growth | AI14: 0.1052 | AJ14: 0.102 | AK14: 0.1306 | AL14: 0.1049 | AM14: 0.0616 | AN14: 0.0675 | AO14: 0.0566 | AP14: 0.0427 | AR14: Estimated Net Income Low | AW14: 91839.249 | AX14: 92114.285
P15: Enterprise Value | U15: 683218830400 | V15: 899472337040 | W15: 1207295911520 | X15: 1069769792560 | Y15: 2032557921320 | Z15: 2555332882240 | AA15: 2548201314090 | AB15: 2789534789510 | AD15: Operating Cash Flow Growth | AI15: -0.185 | AJ15: -0.0303 | AK15: 0.2057 | AL15: -0.1039 | AM15: 0.1626 | AN15: 0.2896 | AO15: 0.1741 | AP15: -0.095 | AR15: Estimated Net Income High | AW15: 103321.44 | AX15: 103094.72
B16: Cost And Expenses | G16: {=_xldudf_WISE(C2,B16:B17,G4:N4)/1000000} -> 155615 | H16: 167890 | I16: 194697 | J16: 196244 | K16: 208227 | L16: 256868 | M16: 274891 | N16: 268984 | P16: Pe Ratio | U16: 13.497731 | V16: 16.630087 | W16: 18.792325 | X16: 18.288816 | Y16: 33.935934 | Z16: 25.916254 | AA16: 24.441824 | AB16: 27.790812 | AD16: Free Cash Flow Growth | AI16: -0.245 | AJ16: -0.0238 | AK16: 0.2468 | AL16: -0.0815 | AM16: 0.2457 | AN16: 0.267 | AO16: 0.1989 | AP16: -0.1064 | AR16: Estimated Net Income AVG | AW16: 100389 | AX16: 97294
B17: EBITDA | G17: 73333 | H17: 76569 | I17: 87046 | J17: 81860 | K17: 81020 | L17: 123136 | M17: 133138 | N17: 129188 | P17: Price To Sales Ratio | U17: 2.859737 | V17: 3.5076879 | W17: 4.2121497 | X17: 3.8841959 | Y17: 7.0972294 | Z17: 6.7075912 | AA17: 6.1861377 | AB17: 7.0328079 | AD17: Ten YRevenue Growth Per Share | AI17: 11.0573 | AJ17: 10.0772 | AK17: 9.1837 | AL17: 7.2669 | AM17: 5.1765 | AN17: 4.2365 | AO17: 3.0669 | AP17: 2.6905 | AR17: Estimated SGA Expense Low | AW17: 23584.887 | AX17: 25098.202
B18: EBITDA Ratio | G18: {=_xldudf_WISE($C$2,$B18,G$4:N$4)} -> 0.34007299 | H18: 0.33402113 | I18: 0.3277396 | J18: 0.31463559 | K18: 0.2951387 | L18: 0.33660546 | M18: 0.33763263 | N18: 0.33705467 | P18: Pocfratio | U18: 9.3109092 | V18: 12.519756 | W18: 14.447477 | X18: 14.56337 | Y18: 24.150233 | Z18: 23.585141 | AA18: 19.970097 | AB18: 24.384808 | AD18: Five YRevenue Growth Per Share | AI18: 1.3558 | AJ18: 0.8371 | AK18: 1.0313 | AL18: 0.8757 | AM18: 0.5578 | AN18: 1.2228 | AO18: 1.2138 | AP18: 0.8168 | AR18: Estimated SGA Expense High | AW18: 25824.901 | AX18: 25243.594
B19: Interest Expense | G19: {=_xldudf_WISE($C$2,$B19:$B21,G$4:N$4)/1000000} -> 1456 | H19: 2323 | I19: 3240 | J19: 3576 | K19: 2873 | L19: 2645 | M19: 2931 | N19: 3933 | P19: Pfcf Ratio | U19: 11.70531 | V19: 15.634481 | W19: 17.447106 | X19: 17.158496 | Y19: 26.556204 | Z19: 26.397759 | AA19: 21.888924 | AB19: 27.068302 | AD19: Three YRevenue Growth Per Share | AI19: 0.4938 | AJ19: 0.4628 | AK19: 0.3194 | AL19: 0.4294 | AM19: 0.4402 | AN19: 0.6347 | AO19: 0.7264 | AP19: 0.5388 | AR19: Estimated SGA Expense AVG | AW19: 24562.195 | AX19: 25132.298
B20: Depreciation And Amortization | G20: 10505 | H20: 10157 | I20: 10903 | J20: 12547 | K20: 11056 | L20: 11284 | M20: 11104 | N20: 11519 | P20: Pb Ratio | U20: 4.808387 | V20: 5.998503 | W20: 10.441038 | X20: 11.167965 | Y20: 29.81827 | Z20: 38.892865 | AA20: 48.14034 | AB20: 43.374791 | AD20: Ten YOperating CFGrowth Per Share | AI20: 31.2201 | AJ20: 12.6203 | AK20: 9.0492 | AL20: 8.2464 | AM20: 5.3669 | AN20: 3.2956 | AO20: 2.877 | AP20: 2.3897 | AR20: Estimated EPS AVG | AW20: {=_xldudf_WISE($C$2,$AR20:$AR24,AW$4:AX$4)} -> 6.45457 | AX20: 6.70821
B21: Operating Income | G21: 60024 | H21: 61344 | I21: 70898 | J21: 63930 | K21: 66288 | L21: 108949 | M21: 119437 | N21: 114301 | P21: Ptb Ratio | U21: 4.808387 | V21: 5.998503 | W21: 10.441038 | X21: 11.167965 | Y21: 29.81827 | Z21: 38.892865 | AA21: 48.14034 | AB21: 43.374791 | AD21: Five YOperating CFGrowth Per Share | AI21: 1.0871 | AJ21: 0.584 | AK21: 0.886 | AL21: 0.5314 | AM21: 0.3166 | AN21: 1.0582 | AO21: 1.4477 | AP21: 0.7973 | AR21: Estimated EPS High | AW21: 6.88594 | AX21: 6.87083
B22: Operating Income Ratio | G22: {=_xldudf_WISE($C$2,$B22,G$4:N$4)} -> 0.2783541 | H22: 0.26760428 | I22: 0.26694027 | J22: 0.24572017 | K22: 0.24147314 | L22: 0.29782378 | M22: 0.30288744 | N22: 0.29821412 | P22: Ev To Sales | U22: 3.1683454 | V22: 3.9238173 | W22: 4.5456274 | X22: 4.1117475 | Y22: 7.404178 | Z22: 6.9852765 | AA22: 6.4621364 | AB22: 7.2779649 | AD22: Three YOperating CFGrowth Per Share | AI22: 0.4612 | AJ22: 0.2546 | AK22: 0.1063 | AL22: 0.2412 | AM22: 0.5107 | AN22: 0.5946 | AO22: 1.0052 | AP22: 0.5102 | AR22: Estimated EPS Low | AW22: 6.1207 | AX22: 6.13903
P23: Enterprise Value Over EBITDA | U23: 9.3166628 | V23: 11.747213 | W23: 13.869631 | X23: 13.068285 | Y23: 25.087113 | Z23: 20.752119 | AA23: 19.139549 | AB23: 21.592832 | AD23: Ten YNet Income Growth Per Share | AI23: 23.8071 | AJ23: 15.0483 | AK23: 14.3365 | AL23: 8.0831 | AM23: 5.0125 | AN23: 4.6597 | AO23: 2.8602 | AP23: 3.3097 | AR23: Number Analyst Estimated Revenue | AW23: 22 | AX23: 25
B24: Total Other Income Expenses Net | G24: {=_xldudf_WISE($C$2,$B24:$B25,G$4:N$4)/1000000} -> 1348 | H24: 2745 | I24: 2005 | J24: 1807 | K24: 803 | L24: 258 | M24: -334 | N24: -565 | P24: Ev To Operating Cash Flow | U24: 10.315696 | V24: 14.005019 | W24: 15.59129 | X24: 15.41655 | Y24: 25.194709 | Z24: 24.561534 | AA24: 20.861076 | AB24: 25.234839 | AD24: Five YNet Income Growth Per Share | AI24: 1.0843 | AJ24: 0.4531 | AK24: 1.101 | AL24: 0.843 | AM24: 0.4261 | AN24: 1.7154 | AO24: 1.6564 | AP24: 1.0513 | AR24: Number Analysts Estimated EPS | AW24: 24 | AX24: 26
B25: Income Before Tax | G25: 61372 | H25: 64089 | I25: 72903 | J25: 65737 | K25: 67091 | L25: 109207 | M25: 119103 | N25: 113736 | P25: Ev To Free Cash Flow | U25: 12.968488 | V25: 17.489254 | W25: 18.828401 | X25: 18.163709 | Y25: 27.704736 | Z25: 27.490591 | AA25: 22.865513 | AB25: 28.011877 | AD25: Three YNet Income Growth Per Share | AI25: 0.4605 | AJ25: 0.4274 | AK25: 0.2945 | AL25: 0.4329 | AM25: 0.428 | AN25: 0.8876 | AO25: 1.0574 | AP25: 0.862
B26: Income Before Tax Ratio | G26: {=_xldudf_WISE($C$2,$B26,G$4:N$4)} -> 0.28460529 | H26: 0.27957895 | I26: 0.27448935 | J26: 0.25266552 | K26: 0.2443983 | L26: 0.29852905 | M26: 0.30204043 | N26: 0.29674002 | P26: Earnings Yield | U26: 0.074086527 | V26: 0.060131976 | W26: 0.053213213 | X26: 0.054678227 | Y26: 0.02946729 | Z26: 0.038585824 | AA26: 0.040913478 | AB26: 0.035983116 | AD26: Ten YShareholders Equity Growth Per Share | AI26: 12.8729 | AJ26: 9.7004 | AK26: 4.9844 | AL26: 2.8715 | AM26: 1.0064 | AN26: 0.276 | AO26: -0.3081 | AP26: -0.1722
B27: Income Tax Expense | G27: {=_xldudf_WISE($C$2,$B27:$B28,G$4:N$4)/1000000} -> 15685 | H27: 15738 | I27: 13372 | J27: 10481 | K27: 9680 | L27: 14527 | M27: 19300 | N27: 16741 | P27: Free Cash Flow Yield | U27: 0.085431315 | V27: 0.063961191 | W27: 0.057316094 | X27: 0.058280166 | Y27: 0.037655984 | Z27: 0.037882004 | AA27: 0.045685207 | AB27: 0.036943581 | AD27: Five YShareholders Equity Growth Per Share | AI27: 0.9796 | AJ27: 0.4223 | AK27: 0.1336 | AL27: 0.069 | AM27: -0.274 | AN27: -0.3554 | AO27: -0.5135 | AP27: -0.2698
B28: Net Income | G28: 45687 | H28: 48351 | I28: 59531 | J28: 55256 | K28: 57411 | L28: 94680 | M28: 99803 | N28: 96995 | P28: Debt To Equity | U28: 0.67861738 | V28: 0.86298089 | W28: 1.0684667 | X28: 1.1940478 | Y28: 1.8714397 | Z28: 2.1639246 | AA28: 2.6144616 | AB28: 1.994175 | AD28: Three YShareholders Equity Growth Per Share | AI28: 0.229 | AJ28: 0.4017 | AK28: 0.0423 | AL28: -0.1641 | AM28: -0.4138 | AN28: -0.3012 | AO28: -0.3621 | AP28: 0.0483
P29: Debt To Assets | U29: 0.27054954 | V29: 0.30821781 | W29: 0.31303028 | X29: 0.31917841 | Y29: 0.37753174 | Z29: 0.38894935 | AA29: 0.37555811 | AB29: 0.35149171 | AD29: Ten YDividendper Share Growth Per Share | AI29: 0 | AJ29: 0 | AK29: 0 | AL29: 0 | AM29: 0 | AN29: 0 | AO29: 8.6284 | AP29: 1.3406
B30: Net Income Ratio | G30: {=_xldudf_WISE($C$2,$B30:$B32,G$4:N$4)} -> 0.21186798 | H30: 0.21092421 | I30: 0.22414202 | J30: 0.21238094 | K30: 0.20913611 | L30: 0.25881793 | M30: 0.25309641 | N30: 0.25306234 | P30: Net Debt To EBITDA | U30: 0.90747685 | V30: 1.2458175 | W30: 1.017508 | X30: 0.72322258 | Y30: 1.0400148 | Z30: 0.82495777 | AA30: 0.81745257 | AB30: 0.72735084 | AD30: Five YDividendper Share Growth Per Share | AI30: 0 | AJ30: 5.4371 | AK30: 0.6966 | AL30: 0.6724 | AM30: 0.6154 | AN30: 0.5601 | AO30: 0.4958 | AP30: 0.3795
B31: EPS | G31: 2.09 | H31: 2.32 | I31: 3 | J31: 2.99 | K31: 3.31 | L31: 5.67 | M31: 6.15 | N31: 6.16 | P31: Current Ratio | U31: 1.3526694 | V31: 1.2760628 | W31: 1.1329262 | X31: 1.5401256 | Y31: 1.3636044 | Z31: 1.0745531 | AA31: 0.87935603 | AB31: 0.98801167 | AD31: Three YDividendper Share Growth Per Share | AI31: 0.3617 | AJ31: 0.3387 | AK31: 0.3771 | AL31: 0.3767 | AM31: 0.3262 | AN31: 0.2522 | AO31: 0.1973 | AP31: 0.176
B32: EPS Diluted | G32: 2.08 | H32: 2.3 | I32: 2.98 | J32: 2.97 | K32: 3.28 | L32: 5.61 | M32: 6.11 | N32: 6.13 | P32: Interest Coverage | U32: 41.225275 | V32: 26.407232 | W32: 21.882099 | X32: 17.877517 | Y32: 23.072746 | Z32: 41.190548 | AA32: 40.749574 | AB32: 29.062039 | AD32: Receivables Growth | AI32: -0.0344 | AJ32: 0.2176 | AK32: 0.3734 | AL32: -0.0651 | AM32: -0.1825 | AN32: 0.3755 | AO32: 0.183 | AP32: 0.0009
B33: Weighted Average Shs Out | G33: {=_xldudf_WISE($C$2,$B33:$B34,G$4:N$4)/1000000} -> 21883.28 | H33: 20868.968 | I33: 19821.508 | J33: 18471.336 | K33: 17352.119 | L33: 16701.272 | M33: 16215.963 | N33: 15744.231 | P33: Income Quality | U33: 1.4496684 | V33: 1.3283076 | W33: 1.3007341 | X33: 1.2558093 | Y33: 1.4052011 | Z33: 1.0988382 | AA33: 1.2239211 | AB33: 1.1396773 | AD33: Asset Growth | AI33: 0.1079 | AJ33: 0.1667 | AK33: -0.0256 | AL33: -0.0744 | AM33: -0.0432 | AN33: 0.0837 | AO33: 0.005 | AP33: -0.0005
B34: Weighted Average Shs Out Dil | G34: 22001.124 | H34: 21006.768 | I34: 20000.436 | J34: 18595.652 | K34: 17528.214 | L34: 16864.919 | M34: 16325.819 | N34: 15812.547 | P34: Dividend Yield | U34: 0.01970257 | V34: 0.015880234 | W34: 0.0122568 | X34: 0.013971367 | Y34: 0.0072273415 | Z34: 0.0058958715 | AA34: 0.0060839546 | AB34: 0.0055739607 | AD34: Inventory Growth | AI34: -0.0924 | AJ34: 1.2772 | AK34: -0.1852 | AL34: 0.0379 | AM34: -0.011 | AN34: 0.6203 | AO34: -0.2483 | AP34: 0.28
P35: Payout Ratio | U35: 0.26593998 | V35: 0.26408968 | W35: 0.23033378 | X35: 0.25551976 | Y35: 0.24526659 | Z35: 0.1527989 | AA35: 0.14870294 | AB35: 0.15490489 | AD35: Book Valueper Share Growth | AI35: 0.13 | AJ35: 0.096 | AK35: -0.1584 | AL35: -0.0937 | AM35: -0.2314 | AN35: 0.0032 | AO35: -0.1728 | AP35: 0.2632
B36: Balance Sheet | G36: =G4 -> 2016 | H36: =H4 -> 2017 | I36: =I4 -> 2018 | J36: =J4 -> 2019 | K36: =K4 -> 2020 | L36: =L4 -> 2021 | M36: =M4 -> 2022 | N36: =N4 -> 2023 | P36: Sales General And Administrative To Revenue | U36: 0.065822973 | V36: 0.066573894 | W36: 0.062896515 | X36: 0.070126146 | Y36: 0.07254977 | Z36: 0.060065552 | AA36: 0.063637378 | AB36: 0.065048202 | AD36: Debt Growth | AI36: 0.3529 | AJ36: 0.3292 | AK36: -0.0103 | AL36: -0.0562 | AM36: 0.1317 | AN36: 0.1165 | AO36: -0.0296 | AP36: -0.0645
B37: (in millions $) | P37: Research And Ddevelopement To Revenue | U37: 0.046582483 | V37: 0.050520429 | W37: 0.053600407 | X37: 0.062331363 | Y37: 0.068309564 | Z37: 0.059904269 | AA37: 0.066571484 | AB37: 0.078048971 | AD37: Rdexpense Growth | AI37: 0.2452 | AJ37: 0.1529 | AK37: 0.2293 | AL37: 0.1392 | AM37: 0.1563 | AN37: 0.1686 | AO37: 0.1979 | AP37: 0.1396
B38: Cash And Cash Equivalents | G38: {=_xldudf_WISE($C$2,$B38:$B44,G$4:N$4)/1000000} -> 20484 | H38: 20289 | I38: 25913 | J38: 48844 | K38: 38016 | L38: 34940 | M38: 23646 | N38: 29965 | P38: Intangibles To Total Assets | U38: 0.026796317 | V38: 0.021355167 | W38: 0 | X38: 0 | Y38: 0 | Z38: 0 | AA38: 0 | AB38: 0 | AD38: Sgaexpenses Growth | AI38: -0.0094 | AJ38: 0.0752 | AK38: 0.0946 | AL38: 0.0922 | AM38: 0.0916 | AN38: 0.1033 | AO38: 0.142 | AP38: -0.0065
B39: Short Term Investments | G39: 46671 | H39: 53892 | I39: 40388 | J39: 51713 | K39: 52927 | L39: 27699 | M39: 24658 | N39: 31590 | P39: Capex To Operating Cash Flow | U39: 0.20455678 | V39: 0.19922149 | W39: 0.17192706 | X39: 0.1512444 | Y39: 0.090599202 | Z39: 0.10654761 | AA39: 0.087661992 | AB39: 0.099137892
B40: Cash And Short Term Investments | G40: 67155 | H40: 74181 | I40: 66301 | J40: 100557 | K40: 90943 | L40: 62639 | M40: 48304 | N40: 61555 | P40: Capex To Revenue | U40: 0.062827225 | V40: 0.055816327 | W40: 0.050125191 | X40: 0.040338389 | Y40: 0.026625139 | Z40: 0.030302036 | AA40: 0.027155059 | AB40: 0.028592301
B41: Net Receivables | G41: 29299 | H41: 35673 | I41: 48995 | J41: 45804 | K41: 37445 | L41: 51506 | M41: 60932 | N41: 60985 | P41: Capex To Depreciation | U41: 1.2896716 | V41: 1.2597224 | W41: 1.2210401 | X41: 0.83645493 | Y41: 0.661089 | Z41: 0.98236441 | AA41: 0.96433718 | AB41: 0.95138467
B42: Inventory | G42: 2132 | H42: 4855 | I42: 3956 | J42: 4106 | K42: 4061 | L42: 6580 | M42: 4946 | N42: 6331 | P42: Stock Based Compensation To Revenue | U42: 0.01952337 | V42: 0.021113796 | W42: 0.0201058 | X42: 0.023322853 | Y42: 0.024876601 | Z42: 0.021611899 | AA42: 0.022920006 | AB42: 0.028263564
...

Sheet DCF
B2: Ticker | C2: AAPL | E2: Current Price | G2: {=_xldudf_WISEPRICE(C2,"price")} -> 327.5
B4: Assumptions | S4: Switches | U4: Conservative case | W4: Base case | Y4: Optimistic case
B5: Switches | I5: Conservative case | K5: Base case | M5: Optimistic case | P5: Share Price | S5: =S17 -> 173.48114 | U5: =U17 -> 132.91787 | W5: =W17 -> 200.36151 | Y5: =Y17 -> 318.58736
B6: Revenue growth | D6: 2 | G6: Revenue 2022 | I6: =M22-1% -> 0.0087737631 | M6: =M22+1% -> 0.028773763 | P6: Upside (Downside) | S6: =S5/$G$2-1 -> -0.4702866 | U6: =U5/$G$2-1 -> -0.5941439 | W6: =W5/$G$2-1 -> -0.38820914 | Y6: =Y5/$G$2-1 -> -0.027214168
B7: EBIT margin | D7: 2 | G7: Revenue 2028 | I7: =K7-1% -> 0.04 | K7: 0.05 | M7: =K7+1% -> 0.06
B8: Taxes | D8: 2 | G8: EBIT 2022 | I8: =M25-1% -> 0.32492679 | M8: =M25+1% -> 0.34492679 | P8: DCF Valuation
B9: D&A | D9: 2 | G9: Taxes 2024 | I9: =M28+3% -> 0.17713108 | M9: =M28-3% -> 0.11713108 | S9: Switches | U9: Conservative case | W9: Base case | Y9: Optimistic case
B10: CapEx | D10: 1 | G10: D&A | I10: =M33-0.5% -> 0.024686226 | M10: =M33+0.5% -> 0.034686226 | P10: Terminal value | S10: =(S89*(1+D17))/(D16-D17) -> 1974823.3 | U10: =(S90*(1+I13))/(I12-I13) -> 1455289.3 | W10: =(S91*(1+K13))/(K12-K13) -> 2333037.4 | Y10: =(S92*(1+M13))/(M12-M13) -> 3935554.5
B11: WACC | D11: 2 | G11: CapEx (2028) | I11: =K11+2% -> 0.09 | K11: 0.07 | M11: =K11-2% -> 0.05 | P11: PV of terminal value | S11: =S10/(1+D16)^S94 -> 1077390.3 | U11: =U10/(1+I12)^S94 -> 744803.07 | W11: =W10/(1+K12)^S94 -> 1272818.6 | Y11: =W10/(1+M12)^S94 -> 1357609.5
B12: TGR | D12: 1 | G12: WACC | I12: =K12+1% -> 0.10041947 | K12: =Z27 -> 0.090419471 | M12: =K12-1% -> 0.080419471 | P12: Enterprise value | S12: =SUM(M95:S95)+S10 -> 2567886.4 | U12: =SUM(M96:S96)+U10 -> 1968843.4 | W12: =SUM(M97:S97)+W10 -> 2964858.8 | Y12: =SUM(M98:S98)+Y10 -> 4710831.8
G13: TGR | I13: =K13-0.5% -> 0.025 | K13: 0.03 | M13: =K13+0.5% -> 0.035 | P13: (+) Cash | S13: {=_xldudf_WISE(C2,"Cash and Short Term Investments","TTM")/1000000} -> 68507 | U13: {=_xldudf_WISE(C2,"Cash and Short Term Investments","TTM")/1000000} -> 68507 | W13: {=_xldudf_WISE(C2,"Cash and Short Term Investments","TTM")/1000000} -> 68507 | Y13: {=_xldudf_WISE(C2,"Cash and Short Term Investments","TTM")/1000000} -> 68507
P14: (-) Debt | S14: {=_xldudf_WISE(C2,"Long term debt","TTM")/1000000} -> 74404 | U14: {=_xldudf_WISE(C2,"Long term debt","TTM")/1000000} -> 74404 | W14: {=_xldudf_WISE(C2,"Long term debt","TTM")/1000000} -> 74404 | Y14: {=_xldudf_WISE(C2,"Long term debt","TTM")/1000000} -> 74404
B15: Valuation assumptions | G15: Risk-free rate | I15: =3.44% -> 0.0344 | P15: Equity value | S15: =S12+S13-S14 -> 2561989.4 | U15: =U12+U13-U14 -> 1962946.4 | W15: =W12+W13-W14 -> 2958961.8 | Y15: =Y12+Y13-Y14 -> 4704934.8
B16: WACC | D16: =CHOOSE(D11,I12,K12,M12) -> 0.090419471 | G16: Equity risk premium | I16: 0.09 | P16: Diluted shares outstanding | S16: =I17 -> 14768.115 | U16: =I17 -> 14768.115 | W16: =I17 -> 14768.115 | Y16: =I17 -> 14768.115
B17: TGR | D17: =CHOOSE(D12,I13,K13,M13) -> 0.025 | G17: Dil Shs outstanding | I17: {=_xldudf_WISE(C2,"Weighted Average Shs Out Dil","TTM")/1000000} -> 14768.115 | P17: Share price | S17: =S15/S16 -> 173.48114 | U17: =U15/U16 -> 132.91787 | W17: =W15/W16 -> 200.36151 | Y17: =Y15/Y16 -> 318.58736
B19: Income Statement | E19: 2014 | F19: =G19-1 -> 2017 | G19: =H19-1 -> 2018 | H19: =I19-1 -> 2019 | I19: =J19-1 -> 2020 | J19: =K19-1 -> 2021 | K19: =L19-1 -> 2022 | L19: 2023 | M19: =L19+1 -> 2024 | N19: =M19+1 -> 2025 | P19: WACC
B21: Revenue | E21: {=_xldudf_WISE($C$2,$B21,E$19)/1000000} -> 182795 | F21: {=_xldudf_WISE($C$2,$B21,F$19:L$19)/1000000} -> 229234 | G21: 265595 | H21: 260174 | I21: 274515 | J21: 365817 | K21: 394328 | L21: 383285 | M21: {=_xldudf_WISE($C$2,"Estimated Revenue AVG",M19)/1000000} -> 390480.7 | N21: {=_xldudf_WISE($C$2,"Estimated Revenue AVG",N19)/1000000} -> 415406.88 | P21: Cost of Debt | T21: Cost of Equity | W21: Weight of Debt and Equity
B22: % of growth | F22: =F21/E21-1 -> 0.25404962 | G22: =G21/F21-1 -> 0.15861958 | H22: =H21/G21-1 -> -0.020410776 | I22: =I21/H21-1 -> 0.055120804 | J22: =J21/I21-1 -> 0.33259385 | K22: =K21/J21-1 -> 0.077937876 | L22: =L21/K21-1 -> -0.028004605 | M22: =M21/L21-1 -> 0.018773763 | N22: =N21/M21-1 -> 0.063834603 | P22: Interest expense | S22: {=_xldudf_WISE(C2,"interest expense","TTM")/1000000} -> 0 | T22: Risk-free rate | V22: =I15 -> 0.0344 | W22: Total debt | Y22: =S23 -> 264591 | Z22: =Y22/Y24 -> 0.052139239
P23: Total debt | S23: {=_xldudf_WISE(C2,"total liabilities","TTM")/1000000} -> 264591 | T23: Beta | V23: {=_xldudf_WISEPRICE(C2,"beta")} -> 1.097 | W23: Market cap | Y23: {=_xldudf_WISEPRICE(C2,"Market Cap")/1000000} -> 4810109.1 | Z23: =Y23/Y24 -> 0.94786076
B24: EBIT | E24: {=_xldudf_WISE($C$2,"Operating income",E$19)/1000000} -> 52503 | F24: {=_xldudf_WISE($C$2,"Operating income",F$19:L$19)/1000000} -> 61344 | G24: 70898 | H24: 63930 | I24: 66288 | J24: 108949 | K24: 119437 | L24: 114301 | M24: {=_xldudf_WISE($C$2,"Estimated EBIT AVG",M19)/1000000} -> 130782.45 | N24: {=_xldudf_WISE($C$2,"Estimated EBIT AVG",N19)/1000000} -> 139130.89 | P24: Cost of debt | S24: =S22/S23 -> 0 | T24: Market return | V24: =I16 -> 0.09 | W24: Total | Y24: =SUM(Y22:Y23) -> 5074700.1
B25: % of revenue | F25: =F24/F21 -> 0.26760428 | G25: =G24/G21 -> 0.26694027 | H25: =H24/H21 -> 0.24572017 | I25: =I24/I21 -> 0.24147314 | J25: =J24/J21 -> 0.29782378 | K25: =K24/K21 -> 0.30288744 | L25: =L24/L21 -> 0.29821412 | M25: =M24/M21 -> 0.33492679 | N25: =N24/N21 -> 0.33492679 | P25: Income tax expense | S25: {=_xldudf_WISE(C2,"income tax expense","TTM")/1000000} -> 25095 | T25: Cost of equity | V25: =(V22)+(V23)*(V24-V22) -> 0.0953932
P26: Income before tax | S26: {=_xldudf_WISE(C2,"Income Before Tax","TTM")/1000000} -> 147670
B27: Taxes | E27: {=_xldudf_WISE($C$2,"Income Tax expense",E$19)/1000000} -> 13973 | F27: {=_xldudf_WISE($C$2,"Income Tax expense",F$19:L$19)/1000000} -> 15738 | G27: 13372 | H27: 10481 | I27: 9680 | J27: 14527 | K27: 19300 | L27: 16741 | M27: =M24*M28 -> 19242.163 | N27: =N24*N28 -> 21110.178 | P27: Effective tax rate | S27: =S25/S26 -> 0.16993973 | W27: WACC | Z27: =(S24*Z22)+(V25*Z23) -> 0.090419471
B28: % of EBIT | F28: =F27/F24 -> 0.25655321 | G28: =G27/G24 -> 0.18860899 | H28: =H27/H24 -> 0.16394494 | I28: =I27/I24 -> 0.14602945 | J28: =J27/J24 -> 0.13333762 | K28: =K27/K24 -> 0.16159147 | L28: =L27/L24 -> 0.14646416 | M28: =AVERAGE(J28:L28) -> 0.14713108 | N28: =AVERAGE(K28:M28) -> 0.1517289 | P28: Cost of debt after tax | S28: =S24*(1-S27) -> 0
B30: Cash Flow Items | F30: =F19 -> 2017 | G30: =G19 -> 2018 | H30: =H19 -> 2019 | I30: =I19 -> 2020 | J30: =J19 -> 2021 | K30: =K19 -> 2022 | L30: =L19 -> 2023 | M30: =M19 -> 2024 | N30: =N19 -> 2025
B32: D&A | F32: {=_xldudf_WISE($C$2,"Depreciation And Amortization",F30:L30)/1000000} -> 10157 | G32: 10903 | H32: 12547 | I32: 11056 | J32: 11284 | K32: 11104 | L32: 11519 | M32: =M21*M33 -> 11591.898 | N32: =N21*N33 -> 12171.266 | Q32: =S4 -> Switches | R32: =U4 -> Conservative case | S32: =W4 -> Base case | T32: =Y4 -> Optimistic case
B33: % of revenue | F33: =F32/F21 -> 0.044308436 | G33: =G32/G21 -> 0.041051225 | H33: =H32/H21 -> 0.048225418 | I33: =I32/I21 -> 0.040274666 | J33: =J32/J21 -> 0.030846024 | K33: =K32/K21 -> 0.028159299 | L33: =L32/L21 -> 0.030053355 | M33: =AVERAGE(J33:L33) -> 0.029686226 | N33: =AVERAGE(K33:M33) -> 0.029299626 | Q33: =S5 -> 173.48114 | R33: =U5 -> 132.91787 | S33: =W5 -> 200.36151 | T33: =Y5 -> 318.58736
B34: % of CapEx | F34: =F32/F36 -> 0.79382571 | G34: =G32/G36 -> 0.81897394 | H34: =H32/H36 -> 1.1955217 | I34: =I32/I36 -> 1.5126556 | J34: =J32/J36 -> 1.0179522 | K34: =K32/K36 -> 1.0369817 | L34: =L32/L36 -> 1.0510996 | M34: =M32/M36 -> 1.0349716 | N34: =N32/N36 -> 1.0410798 | Q34: =G2 -> 327.5 | R34: =Q34 -> 327.5 | S34: =R34 -> 327.5 | T34: =S34 -> 327.5
B36: CapEx | F36: {=-_xldudf_WISE($C$2,"Capital Expenditure",F30:L30)/1000000} -> 12795 | G36: 13313 | H36: 10495 | I36: 7309 | J36: 11085 | K36: 10708 | L36: 10959 | M36: =M21*M37 -> 11200.209 | N36: =N21*N37 -> 11691.002
B37: % of revenue | F37: =F36/F21 -> 0.055816327 | G37: =G36/G21 -> 0.050125191 | H37: =H36/H21 -> 0.040338389 | I37: =I36/I21 -> 0.026625139 | J37: =J36/J21 -> 0.030302036 | K37: =K36/K21 -> 0.027155059 | L37: =L36/L21 -> 0.028592301 | M37: =AVERAGE(J37:L37) -> 0.028683132 | N37: =AVERAGE(K37:M37) -> 0.028143497
B39: Change in NWC | F39: {=_xldudf_WISE($C$2,"Change In Working Capital",F30:L30)/1000000} -> -4923 | G39: 34694 | H39: -3488 | I39: 5690 | J39: -4911 | K39: 1200 | L39: -6577 | M39: =M40*M21 -> -3584.7623 | N39: =N40*N21 -> -3225.8817
B40: % of revenue | F40: =F39/F21 -> -0.021475872 | G40: =G39/G21 -> 0.13062746 | H40: =H39/H21 -> -0.013406413 | I40: =I39/I21 -> 0.020727465 | J40: =J39/J21 -> -0.013424745 | K40: =K39/K21 -> 0.0030431519 | L40: =L39/L21 -> -0.017159555 | M40: =AVERAGE(J40:L40) -> -0.0091803827 | N40: =AVERAGE(K40:M40) -> -0.0077655952
B41: % of change in revenue | G41: =G39/(G21-F21) -> 0.95415418 | H41: =H39/(H21-G21) -> 0.64342372 | I41: =I39/(I21-H21) -> 0.39676452 | J41: =J39/(J21-I21) -> -0.053788526 | K41: =K39/(K21-J21) -> 0.042089018 | L41: =L39/(L21-K21) -> 0.59558091 | M41: =M39/(M21-L21) -> -0.49818105 | N41: =N39/(N21-M21) -> -0.12941741
B43: DCF | F43: =F19 -> 2017 | G43: =G19 -> 2018 | H43: =H19 -> 2019 | I43: =I19 -> 2020 | J43: =J19 -> 2021 | K43: =K19 -> 2022 | L43: =L19 -> 2023 | M43: =M19 -> 2024 | N43: =M43+1 -> 2025 | O43: =N43+1 -> 2026 | P43: =O43+1 -> 2027 | Q43: =P43+1 -> 2028 | R43: =Q43+1 -> 2029 | S43: =R43+1 -> 2030
B45: Revenue | F45: =F21 -> 229234 | G45: =G21 -> 265595 | H45: =H21 -> 260174 | I45: =I21 -> 274515 | J45: =J21 -> 365817 | K45: =K21 -> 394328 | L45: =L21 -> 383285 | M45: =L45*(1+M46) -> 390480.7 | N45: =M45*(1+N46) -> 415406.88 | O45: =N45*(1+O46) -> 440487.47 | P45: =O45*(1+P46) -> 465558.83 | Q45: =P45*(1+Q46) -> 490446.97 | R45: =Q45*(1+R46) -> 514969.32 | S45: =R45*(1+S46) -> 540717.79
B46: % of growth | F46: =F22 -> 0.25404962 | G46: =G22 -> 0.15861958 | H46: =H22 -> -0.020410776 | I46: =I22 -> 0.055120804 | J46: =J22 -> 0.33259385 | K46: =K22 -> 0.077937876 | L46: =L22 -> -0.028004605 | M46: =OFFSET(M46,$D$6,0) -> 0.018773763 | N46: =OFFSET(N46,$D$6,0) -> 0.063834603 | O46: =OFFSET(O46,$D$6,0) -> 0.060375952 | P46: =OFFSET(P46,$D$6,0) -> 0.056917302 | Q46: =OFFSET(Q46,$D$6,0) -> 0.053458651 | R46: =OFFSET(R46,$D$6,0) -> 0.05 | S46: =OFFSET(S46,$D$6,0) -> 0.05
B47: Conservative case | M47: =I6 -> 0.0087737631 | N47: =N48-1% -> 0.053834603 | O47: =N47-(($N$47-$S$47)/($S$43-$O$43)) -> 0.050375952 | P47: =O47-(($N$47-$S$47)/($S$43-$O$43)) -> 0.046917302 | Q47: =P47-(($N$47-$S$47)/($S$43-$O$43)) -> 0.043458651 | R47: =Q47-(($N$47-$S$47)/($S$43-$O$43)) -> 0.04 | S47: =I7 -> 0.04
B48: Base case (Wall Street Estimates) | M48: =M22 -> 0.018773763 | N48: =N22 -> 0.063834603 | O48: =N48-(($N$48-$S$48)/($S$43-$O$43)) -> 0.060375952 | P48: =O48-(($N$48-$S$48)/($S$43-$O$43)) -> 0.056917302 | Q48: =P48-(($N$48-$S$48)/($S$43-$O$43)) -> 0.053458651 | R48: =Q48-(($N$48-$S$48)/($S$43-$O$43)) -> 0.05 | S48: =K7 -> 0.05
B49: Optimistic case | M49: =M6 -> 0.028773763 | N49: =N48+1% -> 0.073834603 | O49: =N49-(($N$49-$S$49)/($S$43-$O$43)) -> 0.070375952 | P49: =O49-(($N$49-$S$49)/($S$43-$O$43)) -> 0.066917302 | Q49: =P49-(($N$49-$S$49)/($S$43-$O$43)) -> 0.063458651 | R49: =Q49-(($N$49-$S$49)/($S$43-$O$43)) -> 0.06 | S49: =M7 -> 0.06
B50: Conservative case | M50: =$L$45*(1+M47) -> 386647.85 | N50: =M50*(1+N47) -> 407462.89 | O50: =N50*(1+O47) -> 427989.22 | P50: =O50*(1+P47) -> 448069.32 | Q50: =P50*(1+Q47) -> 467541.8 | R50: =Q50*(1+R47) -> 486243.48 | S50: =R50*(1+S47) -> 505693.21
...

Sheet RATIOS
B2: Ticker | C2: AAPL
B4: Profitability analysis | F4: 2023 | H4: TTM | J4: Com services | L4: Technology
B5: Gross Profit margin | F5: {=_xldudf_WISE($C$2,"Gross Profit Ratio",$F$4)} -> 0.4413113 | H5: {=_xldudf_WISE($C$2,"Gross Profit Ratio",$H$4)} -> 0.47862405 | J5: 0.5029 | L5: 0.4716
B6: Net Income margin | F6: {=_xldudf_WISE($C$2,"Net Income Ratio",$F$4)} -> 0.25306234 | H6: {=_xldudf_WISE($C$2,"Net Income Ratio",$H$4)} -> 0.27151882 | J6: -0.0252 | L6: -0.0321
B7: ROA | F7: {=_xldudf_WISE($C$2,"Return On Tangible Assets",$F$4)} -> 0.27509835 | H7: {=_xldudf_WISE($C$2,"Return On Tangible Assets",$H$4)} -> 0.35046662 | J7: -0.0345 | L7: -0.0178
B8: ROE | F8: {=_xldudf_WISE($C$2,"ROE",$F$4)} -> 1.5607601 | H8: {=_xldudf_WISE($C$2,"ROE",$H$4)} -> 1.4668924 | J8: -0.0203 | L8: -0.0155
B9: ROIC | F9: {=_xldudf_WISE($C$2,"ROIC",$F$4)} -> 0.43389183 | H9: {=_xldudf_WISE($C$2,"ROIC",$H$4)} -> 0.49573922 | J9: -0.0198 | L9: -0.0094
B11: Market Value analysis | F11: 2023 | H11: TTM | J11: Com services | L11: Technology
B12: PE ratio | F12: {=_xldudf_WISE($C$2,$B12,F$11)} -> 27.790812 | H12: {=_xldudf_WISE($C$2,$B12,H$11)} -> 39.505428 | J12: 12.09 | L12: 22.79
B13: PB ratio | F13: {=_xldudf_WISE($C$2,$B13,F$11)} -> 43.374791 | H13: {=_xldudf_WISE($C$2,$B13,H$11)} -> 45.241008 | J13: 1.42 | L13: 2.53
B14: Price To Sales Ratio | F14: {=_xldudf_WISE($C$2,$B14,F$11)} -> 7.0328079 | H14: {=_xldudf_WISE($C$2,$B14,H$11)} -> 10.654988 | J14: 1.13 | L14: 2.38
B15: Enterprise Value Over EBITDA | F15: {=_xldudf_WISE($C$2,$B15,F$11)} -> 21.592832 | H15: {=_xldudf_WISE($C$2,$B15,H$11)} -> 30.302697 | J15: 4.11 | L15: 4.45
B16: Ev To Sales | F16: {=_xldudf_WISE($C$2,$B16,F$11)} -> 7.2779649 | H16: {=_xldudf_WISE($C$2,$B16,H$11)} -> 10.762162 | J16: 1.55 | L16: 2.27
B18: Liquidity analysis | F18: 2023 | H18: TTM | J18: Com services | L18: Technology
B19: Current ratio | F19: {=_xldudf_WISE($C$2,B19,$F$18)} -> 0.98801167 | H19: {=_xldudf_WISE($C$2,B19,$H$18)} -> 1.0703575 | J19: 1.55 | L19: 2.26
B21: Financial Leverage analysis | F21: 2023 | H21: TTM | J21: Com services | L21: Technology
B22: Debt-to-equity | F22: {=_xldudf_WISE($C$2,"Debt to equity",$F21)} -> 1.994175 | H22: {=_xldudf_WISE($C$2,"Debt to equity",$H21)} -> 0.79547567 | J22: 0.56 | L22: 0.26
B23: Interest Coverage | F23: {=_xldudf_WISE($C$2,B23,$F$21)} -> 29.062039 | H23: {=_xldudf_WISE($C$2,B23,$H$21)} -> 0 | J23: 2.71 | L23: 16.09
B24: Days Sales Outstanding | F24: {=_xldudf_WISE($C$2,B24,$F$21)} -> 58.075649 | H24: {=_xldudf_WISE($C$2,B24,$H$21)} -> 43.264727 | J24: 45.52 | L24: 54.98
B25: Days Payables Outstanding | F25: {=_xldudf_WISE($C$2,B25,$F$21)} -> 106.72147 | H25: {=_xldudf_WISE($C$2,B25,$H$21)} -> 88.933577 | J25: 48.68 | L25: 50.22
B26: Days Of Inventory On Hand | F26: {=_xldudf_WISE($C$2,B26,$F$21)} -> 10.791292 | H26: {=_xldudf_WISE($C$2,B26,$H$21)} -> 10.462865 | J26: 24.83 | L26: 84.73

Sheet Data
B2: =INFO!E2 -> AAPL
B3: close
B5: {=_xldudf_WISEPRICE(B2,B3,365*7)} -> 2026-07-16 | C5: 327.5
B6: 2026-07-15 | C6: 327.5
B7: 2026-07-14 | C7: 314.86
B8: 2026-07-13 | C8: 317.31
B9: 2026-07-10 | C9: 315.32
B10: 2026-07-09 | C10: 316.22
B11: 2026-07-08 | C11: 313.39
B12: 2026-07-07 | C12: 310.66
B13: 2026-07-06 | C13: 312.66
B14: 2026-07-02 | C14: 308.63
B15: 2026-07-01 | C15: 294.38
B16: 2026-06-30 | C16: 289.36
B17: 2026-06-29 | C17: 281.74
... B1761: 2019-07-19 | C1761: 50.65

Sheet AAPL - Income Statement FY
A1: Income Statement
A2: Company | B2: AAPL (NASDAQ)
A3: Currency | B3: USD
A4: Period | B4: FY
A5: Date | B5: 45927 | C5: 45563 | D5: 45199 | E5: 44828 | F5: 44464 | G5: 44100 | H5: 43736 | I5: 43372 | J5: 43008 | K5: 42637 | L5: 42273 | M5: 41909 | N5: 41545 | O5: 41181 | P5: 40810 | Q5: 40446 | R5: 40082 | S5: 39718 | T5: 39354
A7: Revenue | B7: 416161000000 | C7: 391035000000 | D7: 383285000000 | E7: 394328000000 | F7: 365817000000 | G7: 274515000000 | H7: 260174000000 | I7: 265595000000 | J7: 229234000000 | K7: 215639000000 | L7: 233715000000 | M7: 182795000000 | N7: 170910000000 | O7: 156508000000 | P7: 108249000000 | Q7: 65225000000 | R7: 42603000000 | S7: 32479000000 | T7: 24006000000
A9: Cost Of Revenue | B9: 220960000000 | C9: 210352000000 | D9: 214137000000 | E9: 223546000000 | F9: 212981000000 | G9: 169559000000 | H9: 161782000000 | I9: 163756000000 | J9: 141048000000 | K9: 131376000000 | L9: 140089000000 | M9: 112258000000 | N9: 106606000000 | O9: 87846000000 | P9: 64431000000 | Q9: 39541000000 | R9: 25751000000 | S9: 21334000000 | T9: 15852000000
A10: Gross Profit | B10: 195201000000 | C10: 180683000000 | D10: 169148000000 | E10: 170782000000 | F10: 152836000000 | G10: 104956000000 | H10: 98392000000 | I10: 101839000000 | J10: 88186000000 | K10: 84263000000 | L10: 93626000000 | M10: 70537000000 | N10: 64304000000 | O10: 68662000000 | P10: 43818000000 | Q10: 25684000000 | R10: 16852000000 | S10: 11145000000 | T10: 8154000000
A11: Gross Profit Ratio | B11: 0.46905164 | C11: 0.4620635 | D11: 0.4413113 | E11: 0.43309631 | F11: 0.4177936 | G11: 0.38233248 | H11: 0.37817768 | I11: 0.38343719 | J11: 0.3846986 | K11: 0.39075956 | L11: 0.40059902 | M11: 0.38588036 | N11: 0.37624481 | O11: 0.4387124 | P11: 0.40478896 | Q11: 0.39377539 | R11: 0.395559 | S11: 0.3431448 | T11: 0.33966508
A13: Research And Development Expenses | B13: 34550000000 | C13: 31370000000 | D13: 29915000000 | E13: 26251000000 | F13: 21914000000 | G13: 18752000000 | H13: 16217000000 | I13: 14236000000 | J13: 11581000000 | K13: 10045000000 | L13: 8067000000 | M13: 6041000000 | N13: 4475000000 | O13: 3381000000 | P13: 2429000000 | Q13: 1782000000 | R13: 1333000000 | S13: 1109000000 | T13: 782000000
A14: Selling General And Administrative Expenses | B14: 27601000000 | C14: 26097000000 | D14: 24932000000 | E14: 25094000000 | F14: 21973000000 | G14: 19916000000 | H14: 18245000000 | I14: 16705000000 | J14: 15261000000 | K14: 14194000000 | L14: 14329000000 | M14: 11993000000 | N14: 10830000000 | O14: 10040000000 | P14: 7599000000 | Q14: 5517000000 | R14: 4149000000 | S14: 3761000000 | T14: 2963000000
A15: General And Administrative Expenses | B15: 27601000000 | C15: 7458000000 | D15: 0 | E15: 0 | F15: 0 | G15: 0 | H15: 0 | I15: 0 | J15: 0 | K15: 0 | L15: 0 | M15: 0 | N15: 9730000000 | O15: 9040000000 | P15: 0 | Q15: 0 | R15: 0 | S15: 0 | T15: 0
A16: Selling And Marketing Expenses | B16: 0 | C16: 18639000000 | D16: 0 | E16: 0 | F16: 0 | G16: 0 | H16: 0 | I16: 0 | J16: 0 | K16: 0 | L16: 0 | M16: 0 | N16: 1100000000 | O16: 1000000000 | P16: 0 | Q16: 0 | R16: 0 | S16: 0 | T16: 0
A17: Other Expenses | B17: 0 | C17: 0 | D17: 0 | E17: 0 | F17: 0 | G17: 0 | H17: 0 | I17: 0 | J17: 0 | K17: 0 | L17: 0 | M17: 0 | N17: 0 | O17: 0 | P17: 0 | Q17: 0 | R17: 0 | S17: 0 | T17: 0
A18: Operating Expenses | B18: 62151000000 | C18: 57467000000 | D18: 54847000000 | E18: 51345000000 | F18: 43887000000 | G18: 38668000000 | H18: 34462000000 | I18: 30941000000 | J18: 26842000000 | K18: 24239000000 | L18: 22396000000 | M18: 18034000000 | N18: 15305000000 | O18: 13421000000 | P18: 10028000000 | Q18: 7299000000 | R18: 5482000000 | S18: 4870000000 | T18: 3745000000
A20: Cost And Expenses | B20: 283111000000 | C20: 267819000000 | D20: 268984000000 | E20: 274891000000 | F20: 256868000000 | G20: 208227000000 | H20: 196244000000 | I20: 194697000000 | J20: 167890000000 | K20: 155615000000 | L20: 162485000000 | M20: 130292000000 | N20: 121911000000 | O20: 101267000000 | P20: 74459000000 | Q20: 46840000000 | R20: 31233000000 | S20: 26204000000 | T20: 19597000000
... A38: Weighted Average Shs Out Dil | B38: 15004697000 | C38: 15408095000 | D38: 15812547000 | E38: 16325819000 | F38: 16864919000 | G38: 17528214000 | H38: 18595652000 | I38: 20000436000 | J38: 21006768000 | K38: 22001124000 | L38: 23172276000 | M38: 24490652000 | N38: 26086536000 | O38: 26469932000 | P38: 26226060000 | Q38: 25891961891 | R38: 25396165396 | S38: 25259892000 | T38: 24900176000

Sheet AAPL - Balance Sheet FY
A1: Balance Sheet
A2: Company | B2: AAPL (NASDAQ)
A3: Currency | B3: ='AAPL - Income Statement FY'!B3 -> USD
A4: Period | B4: FY
A5: Date | B5: 45927 | C5: 45563 | D5: 45199 | E5: 44828 | F5: 44464 | G5: 44100 | H5: 43736 | I5: 43372 | J5: 43008 | K5: 42637 | L5: 42273 | M5: 41909 | N5: 41545 | O5: 41181 | P5: 40810 | Q5: 40446 | R5: 40082 | S5: 39718 | T5: 39354
A7: Cash And Cash Equivalents | B7: 35934000000 | C7: 29943000000 | D7: 29965000000 | E7: 23646000000 | F7: 34940000000 | G7: 38016000000 | H7: 48844000000 | I7: 25913000000 | J7: 20289000000 | K7: 20484000000 | L7: 21120000000 | M7: 13844000000 | N7: 14259000000 | O7: 10746000000 | P7: 9815000000 | Q7: 11261000000 | R7: 5263000000 | S7: 11875000000 | T7: 9352000000
A8: Short Term Investments | B8: 18763000000 | C8: 35228000000 | D8: 31590000000 | E8: 24658000000 | F8: 27699000000 | G8: 52927000000 | H8: 51713000000 | I8: 40388000000 | J8: 53892000000 | K8: 46671000000 | L8: 20481000000 | M8: 11233000000 | N8: 26287000000 | O8: 18383000000 | P8: 16137000000 | Q8: 14359000000 | R8: 18201000000 | S8: 10236000000 | T8: 6034000000
A9: Cash And Short Term Investments | B9: 54697000000 | C9: 65171000000 | D9: 61555000000 | E9: 48304000000 | F9: 62639000000 | G9: 90943000000 | H9: 100557000000 | I9: 66301000000 | J9: 74181000000 | K9: 67155000000 | L9: 41601000000 | M9: 25077000000 | N9: 40546000000 | O9: 29129000000 | P9: 25952000000 | Q9: 25620000000 | R9: 23464000000 | S9: 22111000000 | T9: 15386000000
A10: Net Receivables | B10: 72957000000 | C10: 66243000000 | D10: 60985000000 | E10: 60932000000 | F10: 51506000000 | G10: 37445000000 | H10: 45804000000 | I10: 48995000000 | J10: 35673000000 | K10: 29299000000 | L10: 30343000000 | M10: 27219000000 | N10: 20641000000 | O10: 18692000000 | P10: 11717000000 | Q10: 9924000000 | R10: 5057000000 | S10: 4704000000 | T10: 4029000000
A11: Inventory | B11: 5718000000 | C11: 7286000000 | D11: 6331000000 | E11: 4946000000 | F11: 6580000000 | G11: 4061000000 | H11: 4106000000 | I11: 3956000000 | J11: 4855000000 | K11: 2132000000 | L11: 2349000000 | M11: 2111000000 | N11: 1764000000 | O11: 791000000 | P11: 776000000 | Q11: 1051000000 | R11: 455000000 | S11: 509000000 | T11: 346000000
A12: Other Current Assets | B12: 14585000000 | C12: 14287000000 | D12: 14695000000 | E12: 21223000000 | F12: 14111000000 | G12: 11264000000 | H12: 12352000000 | I12: 12087000000 | J12: 13936000000 | K12: 8283000000 | L12: 15085000000 | M12: 14124000000 | N12: 10335000000 | O12: 9041000000 | P12: 6543000000 | Q12: 5083000000 | R12: 2579000000 | S12: 2682000000 | T12: 2195000000
A13: Total Current Assets | B13: 147957000000 | C13: 152987000000 | D13: 143566000000 | E13: 135405000000 | F13: 134836000000 | G13: 143713000000 | H13: 162819000000 | I13: 131339000000 | J13: 128645000000 | K13: 106869000000 | L13: 89378000000 | M13: 68531000000 | N13: 73286000000 | O13: 57653000000 | P13: 44988000000 | Q13: 41678000000 | R13: 31555000000 | S13: 30006000000 | T13: 21956000000
A15: Property Plant Equipment Net | B15: 49834000000 | C15: 45680000000 | D15: 54376000000 | E15: 52534000000 | F15: 49527000000 | G15: 45336000000 | H15: 37378000000 | I15: 41304000000 | J15: 33783000000 | K15: 27010000000 | L15: 22471000000 | M15: 20624000000 | N15: 16597000000 | O15: 15452000000 | P15: 7777000000 | Q15: 4768000000 | R15: 2954000000 | S15: 2455000000 | T15: 1832000000
A16: Goodwill | B16: 0 | C16: 0 | D16: 0 | E16: 0 | F16: 0 | G16: 0 | H16: 0 | I16: 0 | J16: 5717000000 | K16: 5414000000 | L16: 5116000000 | M16: 4616000000 | N16: 1577000000 | O16: 1135000000 | P16: 896000000 | Q16: 741000000 | R16: 206000000 | S16: 207000000 | T16: 38000000
A17: Intangible Assets | B17: 0 | C17: 0 | D17: 0 | E17: 0 | F17: 0 | G17: 0 | H17: 0 | I17: 0 | J17: 2298000000 | K17: 3206000000 | L17: 3893000000 | M17: 4142000000 | N17: 4179000000 | O17: 4224000000 | P17: 3536000000 | Q17: 342000000 | R17: 247000000 | S17: 285000000 | T17: 299000000
A18: Goodwill And Intangible Assets | B18: 0 | C18: 0 | D18: 0 | E18: 0 | F18: 0 | G18: 0 | H18: 0 | I18: 0 | J18: 8015000000 | K18: 8620000000 | L18: 9009000000 | M18: 8758000000 | N18: 5756000000 | O18: 5359000000 | P18: 4432000000 | Q18: 1083000000 | R18: 453000000 | S18: 492000000 | T18: 337000000
... A52: Net Debt | B52: 76443000000 | C52: 89116000000 | D52: 93965000000 | E52: 108834000000 | F52: 101582000000 | G52: 84262000000 | H52: 59203000000 | I52: 88570000000 | J52: 95391000000 | K52: 66548000000 | L52: 43208000000 | M52: 21451000000 | N52: 2701000000 | O52: -10746000000 | P52: -9815000000 | Q52: -11261000000 | R52: -5263000000 | S52: -11875000000 | T52: -9352000000

Sheet AAPL - Cash Flow FY
A1: Cash Flow
A2: Company | B2: AAPL (NASDAQ)
A3: Currency | B3: ='AAPL - Income Statement FY'!B3 -> USD
A4: Period | B4: FY
A5: Date | B5: 45927 | C5: 45563 | D5: 45199 | E5: 44828 | F5: 44464 | G5: 44100 | H5: 43736 | I5: 43372 | J5: 43008 | K5: 42637 | L5: 42273 | M5: 41909 | N5: 41545 | O5: 41181 | P5: 40810 | Q5: 40446 | R5: 40082 | S5: 39718 | T5: 39354
A7: Net Income | B7: 112010000000 | C7: 93736000000 | D7: 96995000000 | E7: 99803000000 | F7: 94680000000 | G7: 57411000000 | H7: 55256000000 | I7: 59531000000 | J7: 48351000000 | K7: 45687000000 | L7: 53394000000 | M7: 39510000000 | N7: 37037000000 | O7: 41733000000 | P7: 25922000000 | Q7: 14013000000 | R7: 8235000000 | S7: 6119000000 | T7: 3496000000
A8: Depreciation And Amortization | B8: 11698000000 | C8: 11445000000 | D8: 11519000000 | E8: 11104000000 | F8: 11284000000 | G8: 11056000000 | H8: 12547000000 | I8: 10903000000 | J8: 10157000000 | K8: 10505000000 | L8: 11257000000 | M8: 7946000000 | N8: 6757000000 | O8: 3277000000 | P8: 1814000000 | Q8: 1027000000 | R8: 734000000 | S8: 496000000 | T8: 317000000
